<?xnl version="1.0" ?>
<robot name = "my_robot" xmlns:xacro="http://www.ros.org/wiki/xacro">

	<gazebo reference="link_camera">
		<material>Gazebo/Blue</material>
		<turnGravityOff>false</turnGravityOff>
	</gazebo>
	<gazebo reference="right_front_wheel">
		<material>Gazebo/Red</material>
	</gazebo>
	<gazebo reference="left_front_wheel">
		<material>Gazebo/Red</material>
	</gazebo>
	<gazebo reference="right_back_wheel">
		<material>Gazebo/Red</material>
	</gazebo>
	<gazebo reference="left_back_wheel">
		<material>Gazebo/Red</material>
	</gazebo>

	<gazebo>
		<plugin name="gazebo_ros_control" filename="libgazebo_ros_control.so">
			<robotNamespace>/my_robot</robotNamespace>
			<robotSimType>gazebo_ros_control/DefaultRobotHWSim</robotSimType>
		</plugin>
	</gazebo>

	<gazebo>
		<plugin name="differential_drive_controller" filename="libgazebo_ros_diff_drive.so">
			<alwaysOn>true</alwaysOn>
			<updateRate>50.0</updateRate>
			<leftJoint>left_front_wheel_joint</leftJoint>
			<rightJoint>left_back_wheel_joint</rightJoint>
			<wheelSeparation>0.2</wheelSeparation>
			<wheelDiameter>0.05</wheelDiameter>
			<torque>1.0</torque>
			<commandTopic>cmd_vel</commandTopic>
			<odometryTopic>odom</odometryTopic>
			<odometryFrame>odom</odometryFrame>
			<robotBaseFrame>link_chassis</robotBaseFrame>
			<publishWheelTF>true</publishWheelTF>
			<publishWheelJointState>true</publishWheelJointState>
			<legecyMode>true</legecyMode>
			<wheelAcceleration>1</wheelAcceleration>
			<rosDebugLevel>na</rosDebugLevel>
			<publishOdomTF>true</publishOdomTF>
			<wheelTorque>5</wheelTorque>
			<odometrySource>world</odometrySource>
			<publishTf>1</publishTf>
		</plugin>
	</gazebo>

	<gazebo>
		<plugin name="differential_drive_controller" filename="libgazebo_ros_diff_drive.so">
			<alwaysOn>true</alwaysOn>
			<updateRate>50.0</updateRate>
			<leftJoint>right_front_wheel_joint</leftJoint>
			<rightJoint>right_back_wheel_joint</rightJoint>
			<wheelSeparation>0.2</wheelSeparation>
			<wheelDiameter>0.05</wheelDiameter>
			<torque>1.0</torque>
			<commandTopic>cmd_vel</commandTopic>
			<odometryTopic>odom</odometryTopic>
			<odometryFrame>odom</odometryFrame>
			<robotBaseFrame>link_chassis</robotBaseFrame>
			<publishWheelTF>true</publishWheelTF>
			<publishWheelJointState>true</publishWheelJointState>
			<legecyMode>true</legecyMode>
			<wheelAcceleration>1</wheelAcceleration>
			<rosDebugLevel>na</rosDebugLevel>
			<publishOdomTF>true</publishOdomTF>
			<wheelTorque>5</wheelTorque>
			<odometrySource>world</odometrySource>
			<publishTf>1</publishTf>
		</plugin>
	</gazebo>

	<!-- 1st link -->
	<link name="link_chassis">
		<pose>0 0 0 0 0 0</pose>

		<inertial>
			<mass value="50"/>
			<origin xyz="0 0 0" rpy="0 0 0"/>
			<inertia ixx="0" ixy="0" ixz="0" iyy="0" iyz="0" izz="0"/>
		</inertial>

		<collision name="collision_chassis">
			<geometry>
				<box size="0.245 0.265 0.125"/>
			</geometry>
		</collision>

		<visual>
			<origin rpy="0 0 0" xyz="0 0 0"/>
			<geometry>
				<box size="0.245 0.265 0.125"/>
			</geometry>
		</visual>
	</link>

	<joint name="camera_joint" type="fixed">
		<origin xyz="0.0975 0 0.0875" rpy="0 0 0"/>
		<parent link="link_chassis"/>
		<child link="link_camera"/>
	</joint>

	<!-- 2nd link -->
	<link name="link_camera">
		<collision name="collision_camera">
			<origin xyz="0 0 0" rpy="0 0 0"/>
				<geometry>
					<box size="0.05 0.05 0.05"/>
				</geometry>
		</collision>

		<visual>
			<origin xyz="0 0 0" rpy="0 0 0"/>
				<geometry>
					<box size="0.05 0.05 0.05"/>
				</geometry>
			<material name="Blue">
				<color rgba="0.0 0.0 0.8 1.0"/>
			</material>
		</visual>

		<inertial>
			<mass value="5" />
			<origin xyz="0 0 0" rpy="0 0 0"/>
			<inertia ixx="0" ixy="0" ixz="0" iyy="0" iyz="0" izz="0" />
		</inertial>
	</link>

	<!-- 3th link -->
	<link name="right_front_wheel">
		<collision name="right_front_wheel">
			<origin xyz="0 0 0" rpy="1.5707 0 1.5707"/>
				<geometry>
					<cylinder length="0.04" radius="0.025"/>
				</geometry>
		</collision>

		<visual>
			<origin xyz="0 0 0" rpy="1.5707 0 1.5707"/>
				<geometry>
					<cylinder length="0.04" radius="0.025"/>
				</geometry>
			<material name="Red">
				<color rgba="0.8 0.0 0.0 1.0"/>
			</material>
		</visual>

		<inertial>
			<mass value="5" />
			<origin xyz="0 0 0" rpy="1.5707 0 1.5707"/>
			<inertia ixx="0" ixy="0" ixz="0" iyy="0" iyz="0" izz="0" />
		</inertial>
	</link>

	<!-- 4th link -->
	<link name="right_back_wheel">
		<collision name="right_front_wheel">
			<origin xyz="0 0 0" rpy="1.5707 0 1.5707"/>
				<geometry>
					<cylinder length="0.04" radius="0.025"/>
				</geometry>
		</collision>

		<visual>
			<origin xyz="0 0 0" rpy="1.5707 0 1.5707"/>
				<geometry>
					<cylinder length="0.04" radius="0.025"/>
				</geometry>
			<material name="Red">
				<color rgba="0.8 0.0 0.0 1.0"/>
			</material>
		</visual>

		<inertial>
			<mass value="5" />
			<origin xyz="0 0 0" rpy="1.5707 0 1.5707"/>
			<inertia ixx="0" ixy="0" ixz="0" iyy="0" iyz="0" izz="0" />
		</inertial>
	</link>

	<!-- 5th link -->
	<link name="left_front_wheel">
		<collision name="right_front_wheel">
			<origin xyz="0 0 0" rpy="1.5707 0 1.5707"/>
				<geometry>
					<cylinder length="0.04" radius="0.025"/>
				</geometry>
		</collision>

		<visual>
			<origin xyz="0 0 0" rpy="1.5707 0 1.5707"/>
				<geometry>
					<cylinder length="0.04" radius="0.025"/>
				</geometry>
			<material name="Red">
				<color rgba="0.8 0.0 0.0 1.0"/>
			</material>
		</visual>

		<inertial>
			<mass value="5" />
			<origin xyz="0 0 0" rpy="1.5707 0 1.5707"/>
			<inertia ixx="0" ixy="0" ixz="0" iyy="0" iyz="0" izz="0" />
		</inertial>
	</link>

	<!-- 6th link -->
	<link name="left_back_wheel">
		<collision name="right_front_wheel">
			<origin xyz="0 0 0" rpy="1.5707 0 1.5707"/>
				<geometry>
					<cylinder length="0.04" radius="0.025"/>
				</geometry>
		</collision>

		<visual>
			<origin xyz="0 0 0" rpy="1.5707 0 1.5707"/>
				<geometry>
					<cylinder length="0.04" radius="0.025"/>
				</geometry>
			<material name="Red">
				<color rgba="0.8 0.0 0.0 1.0"/>
			</material>
		</visual>

		<inertial>
			<mass value="5" />
			<origin xyz="0 0 0" rpy="1.5707 0 1.5707"/>
			<inertia ixx="0" ixy="0" ixz="0" iyy="0" iyz="0" izz="0" />
		</inertial>
	</link>

	<joint name="left_back_wheel_joint_differential" type="continuous">
		<origin xyz="-0.1 0.1525 -0.07125" rpy="0 0 1.5707"/>
		<axis xyz="1 0 0" rpy="0 0 0"/>
		<parent link="link_chassis"/>
		<child link="left_back_wheel"/>
		<limit effort="100" velocity="100"/>  
		<joint_properties damping="0.0" friction="0.0"/>   
	</joint>
	<joint name="left_front_wheel_joint_differential" type="continuous">
		<origin xyz="0.1 0.1525 -0.07125" rpy="0 0 1.5707"/>
		<axis xyz="1 0 0" rpy="0 0 0"/>
		<parent link="link_chassis"/>
		<child link="left_front_wheel"/>
		<limit effort="100" velocity="100"/>  
		<joint_properties damping="0.0" friction="0.0"/>   
	</joint>
	<joint name="right_back_wheel_joint_differential" type="continuous">
		<origin xyz="-0.1 -0.1525 -0.07125" rpy="0 0 1.5707"/>
		<axis xyz="1 0 0" rpy="0 0 0"/>
		<parent link="link_chassis"/>
		<child link="right_back_wheel"/>
		<limit effort="100" velocity="100"/>  
		<joint_properties damping="0.0" friction="0.0"/>  
	</joint>
	<joint name="right_front_wheel_joint_differential" type="continuous">
		<origin xyz="0.1 -0.1525 -0.07125" rpy="0 0 1.5707"/>
		<axis xyz="1 0 0" rpy="0 0 0"/>
		<parent link="link_chassis"/>
		<child link="right_front_wheel"/>
		<limit effort="100" velocity="100"/>  
		<joint_properties damping="0.0" friction="0.0"/>    
	</joint>
	<!-- transmission frame -->
	<transmission name="left_back_wheel_joint_differential_tran">
		<type>transmission_interface/SimpleTransmission</type>
		<joint name="left_back_wheel_joint_differential">
			<hardwareInterface>hardware_interface/VelocityJointInterface</hardwareInterface>
		</joint>
		<actuator name="left_back_wheel_joint_differential_motor">
			<mechanicalReduction>1</mechanicalReduction>
			<hardwareInterface>hardware_interface/VelocityJointInterface</hardwareInterface>
		</actuator>
	</transmission>

	<transmission name="left_front_wheel_joint_differential_tran">
		<type>transmission_interface/SimpleTransmission</type>
		<joint name="left_front_wheel_joint_differential">
			<hardwareInterface>hardware_interface/VelocityJointInterface</hardwareInterface>
		</joint>
		<actuator name="left_front_wheel_joint_differential_motor">
			<mechanicalReduction>1</mechanicalReduction>
			<hardwareInterface>hardware_interface/VelocityJointInterface</hardwareInterface>
		</actuator>
	</transmission>

	<transmission name="right_front_wheel_joint_differential_tran">
		<type>transmission_interface/SimpleTransmission</type>
		<joint name="right_front_wheel_joint_differential">
			<hardwareInterface>hardware_interface/VelocityJointInterface</hardwareInterface>
		</joint>
		<actuator name="right_front_wheel_joint_differential_motor">
			<mechanicalReduction>1</mechanicalReduction>
			<hardwareInterface>hardware_interface/VelocityJointInterface</hardwareInterface>
		</actuator>
	</transmission>

	<transmission name="right_back_wheel_joint_differential_tran">
		<type>transmission_interface/SimpleTransmission</type>
		<joint name="right_back_wheel_joint_differential">
			<hardwareInterface>hardware_interface/VelocityJointInterface</hardwareInterface>
		</joint>
		<actuator name="right_back_wheel_joint_differential_motor">
			<mechanicalReduction>1</mechanicalReduction>
			<hardwareInterface>hardware_interface/VelocityJointInterface</hardwareInterface>
		</actuator>
	</transmission>

	<!-- camera -->
	<gazebo reference="link_camera">
		<sensor type="camera" name="camera1">
			<update_rate>60</update_rate>
			<camera name="head">
				<horizontal_fov>1.3962634</horizontal_fov>
				<image>
					<width>800</width>
					<height>800</height>
					<format>R8G8B8</format>
				</image>
				<clip>
					<near>0.02</near>
					<far>300</far>
				</clip>
				<noise>
					<type>gaussian</type>
					<!-- Noise is sampled independently per pixel on each frame.
						That pixel's noise value is added to each of its color
						channels, which at that point lie in the range [0,1]. -->
					<mean>0.0</mean>
					<stddev>0.007</stddev>
				</noise>
			</camera>
			<plugin name="camera_controller" filename="libgazebo_ros_camera.so">
				<alwaysOn>true</alwaysOn>
				<updateRate>60</updateRate>
				<cameraName>my_robot/camera1</cameraName>
				<imageTopicName>image_raw</imageTopicName>
				<cameraInfoTopicName>camera_info</cameraInfoTopicName>
				<frameName>link_camera</frameName>
				<hackBaseline>0.07</hackBaseline>
				<distortionK1>0.0</distortionK1>
				<distortionK2>0.0</distortionK2>
				<distortionK3>0.0</distortionK3>
				<distortionT1>0.0</distortionT1>
				<distortionT2>0.0</distortionT2>
			</plugin>
		</sensor>
	</gazebo>
</robot>
